Workbook
Name EndingBalance: -FV(InterestRate/12,PaymentNumber,-MonthlyPayment,LoanAmount)
Name Fabricator: lists!$K$2:$L$2
Name Gym_Package: lists!$C$2:$C$5
Name Gym_Shape: lists!$B$2:$B$4
Name Gym_Type: lists!$A$2:$A$4
Name HeaderRow: ROW(#REF!)
Name InterestAmt: -IPMT(InterestRate/12,PaymentNumber,NumberOfPayments,LoanAmount)
Name InterestRate: #REF!
Name LastRow: MATCH(9.99E+307,#REF!)
Name LoanAmount: #REF!
Name LoanIsGood: IF(LoanAmount*InterestRate*LoanYears*LoanStartDate>0,1,0)
Name LoanIsNotPaid: IF(PaymentNumber<=NumberOfPayments,1,0)
Name LoanStartDate: #REF!
Name LoanValue: -FV(InterestRate/12,PaymentNumber-1,-MonthlyPayment,LoanAmount)
Name LoanYears: #REF!
Name MonthlyPayment: -PMT(InterestRate/12,NumberOfPayments,LoanAmount)
Name NumberOfPayments: #REF!
Name PaymentDate: DATE(YEAR(LoanStartDate),MONTH(LoanStartDate)+PaymentNumber,DAY(LoanStartDate))
Name PaymentNumber: ROW()-HeaderRow
Name Powder_Brand: #REF!
Name Principal: -PPMT(InterestRate/12,PaymentNumber,NumberOfPayments,LoanAmount)
Name Shields: lists!$D$2:$D$3
Name TotalLoanCost: #REF!

Sheet Discovery
A1: PROJECT DISCOVERY INPUT | E1: Project Template Revision Log
A2: Client Name: | B2: =ZAPIER!C5 -> Tyler Galiotto | E2: Revision | F2: Description of changes made | G2: Made by: | H2: Date:
A3: Organization Name: | B3: =ZAPIER!D5 -> Soar Autism Center - South Fort Collins | E3: 1 | F3: Added logo parts and updated pricing and quoting sheet | G3: Kmaurer | H3: 44784
A4: Organization Address: | B4: =ZAPIER!E5 -> 3801 Automation Way | E4: 2 | F4: Added Alternating hole parts | G4: Kmaurer | H4: 44901
A5: Organization City & State: | B5: =ZAPIER!F5&", "&ZAPIER!G5 -> Fort Collins, CO | E5: 3 | F5: Added Margin dollar amount and fixed a couple quote tab issues | G5: Kmaurer | H5: 44932
A6: Organization Zip Code: | B6: =ZAPIER!H5 -> 80525 | E6: 4 | F6: Updated quote tab headers and added low ceiling parts | G6: Kmaurer | H6: 44938
A7: Ship to Address: | B7: =B4 -> 3801 Automation Way | E7: 5 | F7: Added 3 quote options and organized the calcs tabs | G7: Kmaurer | H7: 44978
A8: Ship to City & State: | B8: =B5 -> Fort Collins, CO | E8: 6 | F8: Corrected 1/2" washer price from $11.00 to $0.28 | G8: Kmaurer | H8: 44992
A9: Ship to Zip Code: | B9: =B6 -> 80525 | E9: 7 | F9: Quoting tab; Moved Trolley steel parts into trolley portion | G9: Kmaurer | H9: 45001
A10: Country: | B10: =ZAPIER!I5 -> United States | E10: 8 | F10: Added weight calcs for each component | G10: Kmaurer
A11: Phone: | B11: =ZAPIER!J5 -> 5203895979 | E11: 9 | F11: Corrected 3/8" monkey bar bolt quantities | G11: Kmaurer | H11: 45079
A12: Email Address: | B12: =ZAPIER!K5 | E12: 10 | F12: Updated TRT 2001 from $96 to $106, quote creation time stamp & Goldberg Order Details | G12: Kmaurer | H12: 45098
A13: Project ID: | B13: =ZAPIER!B2 -> 12552093278 | E13: 11 | F13: Added Mail_Workbook macro and email worksheet button to order details tab | G13: Kmaurer | H13: 45101
A14: CUSTOMS & DUTES | B14: =SUM(B15:B16) -> 0 | E14: 12 | F14: Added $100 crating fee to shipping calculations | G14: BShepherd | H14: 45102
A15: Customs Fees | B15: 0 | E15: 13 | F15: Added discount logic to quote page | G15: BShepherd | H15: 45102
A16: Border Buddy Fees | B16: 0 | E16: 14 | F16: Added calculations to quote for accessory brackets, eyebolts, swivel bolt | G16: BShepherd | H16: 45102
A17: TRAVEL | B17: No | E17: 15 | F17: Updated formula on Calcs tab - If quantity is negative, the total will return a zero $ result | G17: BShepherd | H17: 45102
A18: Estimated Travel Expenses | B18: 0 | E18: 16 | F18: Added invoice tab & added payment calculation data for invoice tab | G18: BShepherd | H18: 45112
A19: Estimated Freight Cost-Goldberg | B19: TBD | C19: =IF(B19=0,"TBD",B19) -> TBD | E19: 17 | F19: Updated Goldberg pricing per part based on order details sent and updated 1/2 nuts qty per | G19: KMaurer | H19: 45114
A20: Estimated Freight - 3rd Party Orders | B20: 0 | C20: =IF(B20=0,"TBD",B20) -> TBD | E20: 18 | F20: Added trolley weights to total shipment weight on Goldberg Order Details tab | G20: Kmaurer | H20: 45117
A21: RESILITE INTEREST | B21: Yes | E21: 19 | F21: Add various calculations to Calcs tab - Will allow us to determine max discount rate while still obtaining a 100% mark up | G21: BShepherd | H21: 45120
A22: Estimated Resilite Product Cost | B22: =Calcs!N176 -> 0 | E22: 20 | F22: Add several accessory items to the calcs tab - Product numbers are associated Amazon ASIN # | G22: BShepherd | H22: 45126
B23: ENTER RESILITE RATE FROM WEBSITE
A24: Estimated Freight Cost | B24: 859.14 | C24: =IF(B24=0,"TBD",B24) -> 859.14 | E24: 21 | F24: Corrected 6820H-024 hardware calculation | G24: Kmaurer | H24: 45134
A25: Estimated State & Local Tax | B25: 294.07 | C25: =IF(B25="TBD","TBD",B25) -> 294.07 | E25: 22 | F25: Corrected 6820H-023 description to 5/16" bolt | G25: Kmaurer | H25: 45134
A26: Column Mats | B26: Yes | E26: 23 | F26: Added Calculations for single and double ladder leg sleeves, changed Zip Line kit, TRT-2001 price | G26: Kmaurer | H26: 45145
A27: Floor Mats | B27: Yes | E27: 24 | F27: Corrected calculation for 1/2"-13 X 4.5" Bolt | G27: KMaurer | H27: 45161
A28: Proposal Description Prefix Add-On | E28: 25 | F28: Corrected calculation for 3/8"-16 x 2.25" 6820H-013 | G28: KMaurer | H28: 45181
A29: Product Line: | B29: Summit Adventure Series | E29: 26 | F29: Fixed all the SaveAsPDF macros | G29: KMaurer | H29: 45189
A30: Gym Type: | B30: Clinic | E30: 27 | F30: Added 6820H-031 & 6820H-032 for the V-Ring and hardware. Need to update costs. | G30: KMaurer | H30: 45195
A31: Shape: | B31: Rectangle | E31: 28 | F31: Fixed 6820H-013 3/8"x2.25" bolt quantity calcs | G31: Kmaurer | H31: 45212
A32: Gym Package: | B32: Lien | E32: 29 | F32: Updated entire workbook to switch to <80" member sizes affecting 10' HRZ, Verticals & Corner Posts | G32: Kmaurer | H32: 45239
A33: Tax Exempt | B33: Yes | C33: =IF(B33="No",'Adventure Series Proposal (USA)'!H230-'Adventure Series Proposal (USA)'!H231,"") | E33: 30 | F33: Added Summit Slide and Summit Climb Color selection and udpated Goldberg Order Details | G33: Kmaurer | H33: 45300
A34: Combined Tax Rate | B34: =IF(B33="No",VLOOKUP(B6,#REF!,2,FALSE),0) -> 0 | C34: =IF(B33="No",(C19+C24+C33)*B34,"") | E34: 31 | F34: Added the additional Resilite mat options to the proposal | G34: BShepherd | H34: 45302
A35: Size LENGTH inches (LONG): | B35: 120 | C35: =B35/12 -> 10 | E35: 32 | F35: Transitioned all A-2016 mid saddle brackets to A-2225 | G35: Kmaurer | H35: 45313
A36: Size WIDTH inches (SHORT): | B36: 120 | C36: =B36/12 -> 10 | E36: 33 | F36: Updated P-2209 & P2219 to the <80 A-2409 & A-2419 | G36: Kmaurer | H36: 45329
A37: Size HEIGHT inches: | B37: 96 | C37: =B37/12 -> 8 | E37: 34 | F37: Updated our playground handle cost from $11.99 to $30 that Goldberg is charging us. | G37: Kmaurer | H37: 45362
A38: Number of Accessory Brackets: | B38: 4 | E38: 35 | F38: Updated the Handles from quantity per set of 2 to quantity per handle | G38: Kmaurer | H38: 45363
A39: Number of 3/8" Swivel Eyebolts for accessory saddle brackets | B39: 4 | C39: NOTE: $74.95/each | E39: 36 | F39: Moved Goldberg Order Details tab next to Calcs tab for convenience | G39: Kmaurer | H39: 45368
A40: Number of 3/8" non-swivel eyebolts for accessory saddle brackets | B40: =B38-B39 -> 0 | C40: NOTE: $5.07/each | E40: 37 | F40: Updated Goldberg Order Details tab to mark zipline wire rope and zipline trolley prices as $0 | G40: Kmaurer | H40: 45378
...

Sheet VLOOKUP
A1: Interlocking Floor Padding Calculator | D1: =F3&F12&F4&F5&F7&F8&F17&F18 -> SQ-2MBL2T | F1: =D1&"-"&F9&"x"&F10 -> SQ-2MBL2T-10x10 | J1: Horizontal Beams | M1: L Shape | N1: INTERIOR BEAM | O1: MONKEY BAR | P1: LADDER | R1: TOTAL
A2: LENGTH (Inches) | B2: 120 | H2: PART # | I2: DESCRIPTION | J2: 4 | K2: 7 | L2: 10
A3: WIDTH (Inches) | B3: 120 | D3: Design Layout | E3: Square | F3: {=_xlfn.IFS(E3="-","",E3="Square","SQ-",E3="rectangle","R-",E3="L Shape","L-",E3="T Shape","T-")} -> SQ- | H3: A-2245 | I3: =VLOOKUP(H3,Calcs!C:D,2,FALSE) -> Vertical Tall <80 w/Gusset | J3: =IF(E6=4,4,0) -> 4 | K3: =IF(E6=6,6,0) -> 0 | L3: =IF(E6=8,8,0) -> 0 | P3: =E7*-1 -> -2 | R3: =SUM(J3:N3)+SUM(O3:P3) -> 2
A4: AREA SQ FT | B4: =(B2/12)*(B3/12) -> 100 | D4: Monkey Bars | E4: Yes | F4: =IF(E4="Yes","MB","") -> MB | H4: A-2246 | I4: =VLOOKUP(H4,Calcs!C:D,2,FALSE) -> Vertical Tall <80 w/Gussets, Rungs & Handles | P4: =E7 -> 2 | R4: =SUM(J4:N4)+SUM(O4:P4) -> 2
A5: # of Tiles | B5: =B4/4 -> 25 | D5: # - Monkey Bar Sets | E5: 1 | F5: =IF(E5=2,2,"") | H5: A-2241 | I5: =VLOOKUP(H5,Calcs!C:D,2,FALSE) -> Corner Post <80 1-Way Weld Assembly | R5: =SUM(J5:N5)+SUM(O5:P5) -> 0
A6: 10% Overage | B6: =B5*1.1 -> 27.5 | D6: # - Legs | E6: 4 | H6: A-2242 | I6: =VLOOKUP(H6,Calcs!C:D,2,FALSE) -> Corner Post <80 2-Way Weld Assembly | J6: =IF(E6>0.01,4,0) -> 4 | M6: =IF(E3="L Shape",1,0) -> 0 | R6: =SUM(J6:N6)+SUM(O6:P6) -> 4
A7: 15% Overage | B7: =B5*1.15 -> 28.75 | D7: # - Ladders | E7: 2 | F7: {=_xlfn.IFS(E7=4,"L4",E7=0,"",E7=2,"L2",E7=1,"L1",E7=3,"L3")} -> L2 | H7: A-2243 | I7: =VLOOKUP(H7,Calcs!C:D,2,FALSE) -> Corner Post <80 3-Way Weld Assembly | K7: =IF(E6=6,2,0) -> 0 | L7: =IF(E6=8,4,0) -> 0 | M7: =IF(E3="L Shape",-2,0) -> 0 | R7: =SUM(J7:N7)+SUM(O7:P7) -> 0
D8: Trolley System | E8: Yes | F8: =IF(E8="no","","T") -> T | H8: A-2244 | I8: =VLOOKUP(H8,Calcs!C:D,2,FALSE) -> Corner Post <80 4-Way Weld Assembly | M8: =IF(E3="L Shape",1,0) -> 0 | R8: =SUM(J8:N8)+SUM(O8:P8) -> 0
A9: AREA SQ FT | B9: 895 | D9: Size LENGTH Ft (LONG) | E9: 10 | F9: =Discovery!B35/12 -> 10 | H9: A-2225 | I9: =VLOOKUP(H9,Calcs!C:D,2,FALSE) -> Mid Span 1-Way Saddle Alt Weld Assembly | N9: =E12*2 -> 2 | O9: =IF(E4="Yes",2,0) -> 2 | R9: =SUM(J9:N9)+SUM(O9:P9) -> 4
A10: # of Tiles | B10: =B9/4 -> 223.75 | D10: Size WIDTH Ft (SHORT) | E10: =F10 -> 10 | F10: =Discovery!B36/12 -> 10 | H10: P-2531 | I10: =VLOOKUP(H10,Calcs!C:D,2,FALSE) -> Ladder Leg Footless | P10: =E7 -> 2 | R10: =SUM(J10:N10)+SUM(O10:P10) -> 2
A11: 10% Overage | B11: =B10*1.1 -> 246.125 | D11: Size HEIGHT Ft | E11: =Discovery!C37 -> 8 | F11: =Discovery!B37/12 -> 8 | H11: A-2253 | I11: =VLOOKUP(H11,Calcs!C:D,2,FALSE) -> Single Leg Inner Ladder Sleeve Footless Weld Assembly | P11: =E7*1 -> 2 | R11: =SUM(J11:N11)+SUM(O11:P11) -> 2
A12: 15% Overage | B12: =B10*1.15 -> 257.3125 | D12: Interior Beams | E12: 1 | F12: =IF(E4="Yes",E12+1,E12) -> 2 | H12: A-2248 | I12: =VLOOKUP(H12,Calcs!C:D,2,FALSE) -> Double Leg Inner Ladder Sleeve | R12: =SUM(J12:N12)+SUM(O12:P12) -> 0
H13: P-2545 | I13: 5' Full Bay HSS Member Alt w/Logo | J13: =(VLOOKUP(H13,$D$58:$E$63,2,FALSE))+(VLOOKUP(H13,$D$67:$E$72,2,FALSE)) -> 0 | K13: =IF(AND(E3=6,E6=8),3,0) -> 0 | L13: =IF(AND(E3=8,E6=8),6,0) -> 0 | N13: =IF(E8=6,E11,0) -> 0 | O13: 0 | R13: =SUM(J13:N13)+SUM(O13:P13) -> 0
A14: GermBlock Ball Pit Calculator | D14: Design Fee | E14: No | F14: =IF(E14="Yes",2500,0) -> 0 | H14: P-2206 | I14: 6' Full Bay HSS Member Alt w/Logo | J14: =(VLOOKUP(H14,$D$58:$E$63,2,FALSE))+(VLOOKUP(H14,$D$67:$E$72,2,FALSE)) -> 0 | K14: =IF(AND(E4=6,E7=8),3,0) -> 0 | L14: =IF(AND(E4=8,E7=8),6,0) -> 0 | N14: =IF(E9=6,E12,0) -> 0 | O14: =(O20*-1)*0.5 -> 0 | R14: =SUM(J14:N14)+SUM(O14:P14) -> 0
A15: LENGTH (Inches) | B15: 72 | H15: P-2207 | I15: 7' Full Bay HSS Member Alt w/Logo | J15: =(VLOOKUP(H15,$D$58:$E$63,2,FALSE))+(VLOOKUP(H15,$D$67:$E$72,2,FALSE)) -> 0 | K15: =IF(AND(E5=6,E8=8),3,0) -> 0 | L15: =IF(AND(E5=8,E8=8),6,0) -> 0 | N15: =IF(E9=7,E12,0) -> 0 | O15: =(O21*-1)*0.5 -> 0 | R15: =SUM(J15:N15)+SUM(O15:P15) -> 0
A16: WIDTH (Inches) | B16: 72 | D16: Accessories | H16: A-2408 | I16: =VLOOKUP(H16,Calcs!C:D,2,FALSE) -> 8' Half Bay <80 HSS Member w/Splices & HDWE | J16: =(VLOOKUP(H16,$D$58:$E$63,2,FALSE))+(VLOOKUP(H16,$D$67:$E$72,2,FALSE)) -> 0 | K16: =IF(AND(E6=6,E9=8),3,0) -> 0 | L16: =IF(AND(E6=8,E9=8),6,0) -> 0 | N16: =IF(E9=8,E12,0) -> 0 | O16: =(O24*-1)*0.5 -> 0 | R16: =SUM(J16:N16)+SUM(O16:P16) -> 0
A17: HEIGHT (Inches) | B17: 24 | D17: Zip Line | E17: No | F17: =IF(E17="Yes","Z","") | H17: A-2409 | I17: =VLOOKUP(H17,Calcs!C:D,2,FALSE) -> 9' Half Bay <80 HSS Member w/Splices & HDWE | J17: =(VLOOKUP(H17,$D$61:E63,2,FALSE))+(VLOOKUP(H17,D70:E72,2,FALSE)) -> 0 | K17: =IF(AND(E6=6,E9=9),3,0) -> 0 | L17: =IF(AND(E6=8,E9=9),6,0) -> 0 | N17: =IF(E9=9,E12,0) -> 0 | O17: =(O25*-1)*0.5 -> 0 | R17: =SUM(J17:N17)+SUM(O17:P17) -> 0
A18: CUBIC Ft | B18: =(B15/12)*(B16/12)*(B17/12) -> 72 | D18: Frame Mount - Ball Rack | E18: No | F18: =IF(E18="Yes","R","") | H18: A-2410 | I18: =VLOOKUP(H18,Calcs!C:D,2,FALSE) -> 10' Half Bay <80 HSS Member w/Splices & HDWE | J18: =(VLOOKUP(H18,D61:E63,2,FALSE))+(VLOOKUP(H18,D70:E72,2,FALSE)) -> 4 | K18: =IF(AND(E6=6,E9=10),3,0) -> 0 | L18: =IF(AND(E6=8,E9=10),6,0) -> 0 | N18: =IF(E9=10,E12,0) -> 1 | O18: =(O26*-1)*0.5 -> -1 | R18: =SUM(J18:N18)+SUM(O18:P18) -> 4
D19: Slide | H19: P-2330 | I19: =VLOOKUP(H19,Calcs!C:D,2,FALSE) -> Monkey Bar / Ladder Rungs w/ 4 Threaded Holes | O19: =IF(E4="Yes",9,0) -> 9 | P19: =IF(E7>0.01,E7*5,0) -> 10 | R19: =SUM(J19:N19)+SUM(O19:P19) -> 19
A20: Balls Per Case | B20: 500 | D20: Slide | E20: No | H20: P-2216 | I20: 6' Full Bay Monkey Bar HSS Member w/Logo | O20: =IF(E55="Yes6",2,0) -> 0 | R20: =SUM(J20:N20)+SUM(O20:P20) -> 0
D21: Slide - Gray Upcharge | E21: No | H21: P-2217 | I21: 7' Full Bay Monkey Bar HSS Member w/Logo | O21: =IF(E54="Yes7",2,0) -> 0 | R21: =SUM(J21:N21)+SUM(O21:P21) -> 0
D22: Steamroller Ramp (3rd Party) | E22: No
A23: Ball Pit Cases Required | B23: =B18/7 -> 10.285714 | D23: Slide Conversion Kit | E23: No
D24: Climbing Wall | H24: A-2418 | I24: =VLOOKUP(H24,Calcs!C:D,2,FALSE) -> 8' Half Bay Monkey Bar HSS Member w/ Logo | O24: =IF(E55="Yes8",2,0) -> 0 | R24: =SUM(J24:N24)+SUM(O24:P24) -> 0
A25: Summit Safety Floor Mats | D25: Climbing Wall - Frame Mounted | E25: No | H25: A-2419 | I25: =VLOOKUP(H25,Calcs!C:D,2,FALSE) -> 9' Half Bay <80 Monkey Bar HSS w/Splices & HDWE | O25: =IF(E55="Yes9",2,0) -> 0 | R25: =SUM(J25:N25)+SUM(O25:P25) -> 0
A26: Each Roll is 6' Wide x 42' Long | D26: Climbing Wall - Safety Shield | E26: No | H26: A-2420 | I26: =VLOOKUP(H26,Calcs!C:D,2,FALSE) -> 10' Half Bay <80 Monkey Bar HSS w/Splices & HDWE | O26: =IF(E55="Yes10",2,0) -> 2 | R26: =SUM(J26:N26)+SUM(O26:P26) -> 2
A27: Cost Per SQ FT - Thickness | D27: Climbing Wall - Wall Mounted | E27: Yes | H27: P-2024 | I27: =VLOOKUP(H27,Calcs!C:D,2,FALSE) -> Zip Line HSS Tube | J27: =IF(E17="Yes",2,0) -> 0 | R27: =SUM(J27:N27)+SUM(O27:P27) -> 0
A28: 1-3/8" | B28: 4.75 | D28: Climbing Wall - Mat | E28: No | H28: P-2028 | I28: =VLOOKUP(H28,Calcs!C:D,2,FALSE) -> Base Plate Shield | J28: =J3*2 -> 8 | K28: =K3*2 -> 0 | L28: =L3*2 -> 0 | R28: =SUM(J28:N28)+SUM(O28:P28) -> 8
A29: 2" | B29: 5.75 | D29: Mats & Padding | H29: P-1032 | I29: =VLOOKUP(H29,Calcs!C:D,2,FALSE) -> 4.5' Full Bay HSS Member Alt w/Logo | R29: =SUM(J29:N29)+SUM(O29:P29) -> 0
A30: AREA SQ FT | B30: 21 | D30: Adventure Mat System - Floor | E30: Yes | F30: {=_xlfn.IFS(E6=6,2,E6=8,3,E6=4,1)} -> 1
D31: Adventure Mat System - Column | E31: Yes | F31: =IF(E31="Yes",E6,0) -> 4 | H31: PART # | I31: TROLLEY PARTS | J31: UNIT COUNT | R31: =R1 -> TOTAL
D32: Adventure Mat System - Ladder Leg | E32: Yes | F32: =E7 -> 2 | H32: P-2018 | I32: Trolley Bar | J32: =IF($E$8="Yes",1,0) -> 1 | R32: =J32 -> 1
D33: Adventure Mat System - CUSTOM | E33: No | H33: P-2025 | I33: Trolley Bar Plate | J33: =IF($E$8="Yes",2,0) -> 2 | R33: =J33 -> 2
D34: Ladder | H34: TR2000-A10 | I34: 10' Aluminum Enclosed Rail 550Lbs. Max Weight | J34: 0 | R34: =J34 -> 0
A35: LENGTH (Inches) | B35: 72 | D35: Ladder - Safety Shield | E35: No | H35: TR2000-A09 | I35: 9' Aluminum Enclosed Rail 550Lbs. Max Weight | J35: =IF($E$8="Yes",2,0) -> 2 | R35: =J35 -> 2
A36: WIDTH (Inches) | B36: 42 | D36: MISC | H36: TR2000-A08 | I36: 8' Aluminum Enclosed Rail 550Lbs. Max Weight | J36: 0 | R36: =J36 -> 0
A37: AREA SQ FT | B37: =(B35/12)*(B36/12) -> 21 | D37: Eldo Summit Climbing Wall | E37: No | H37: TR2000-A07 | I37: 7' Aluminum Enclosed Rail 550Lbs. Max Weight | J37: 0 | R37: =J37 -> 0
A38: ROLLS REQUIRED | B38: =B37/B30 -> 1 | D38: Interlocking Tile Mats | E38: No | H38: TRH2005 | I38: Universal Threaded Rod Hanger | J38: =IF($E$8="Yes",6,0) -> 6 | R38: =J38 -> 6
D39: Wheelchair Swing | H39: TRN2016 | I39: End Cap For Rail | J39: =IF($E$8="Yes",4,0) -> 4 | R39: =J39 -> 4
A40: AREA SQ FT | B40: 1000 | D40: Wheelchair Swing | E40: No | H40: TRT2001 | I40: Trolley For Rail | J40: =IF($E$8="Yes",2,0) -> 2 | R40: =J40 -> 2
...

Sheet Calcs
B1: STEEL PARTS | C1: TROLLEY PARTS
L2: Mark Up | M2: 1.3 | N2: =W5-W8 -> 10303.969 | S2: Financial Details
A3: ADVENTURE SERIES: FRAME COST
A4: UPC | C4: PART # | D4: DESCRIPTION | E4: VLOOKUP TEST | F4: ORDER QUANTITY | G4: PRICE PER PART | H4: Price Per w Tax (6.5%) | I4: WEIGHT (LB) | J4: TOTAL PER PART | K4: Total w Tax (6.5%) | L4: PRICE PER PART | M4: TOTAL PER PART | N4: MARK UP | O4: WEIGHT PER PART (LBS) | R4: STRUCTURE | S4: MATS | T4: TROLLEY | U4: ACCESSORIES | V4: HARDWARE | W4: TOTAL | X4: DISCOUNT PROPOSED | Y4: MAX DISCOUNT | Z4: FREIGHT & TAXES
B5: =IF(F5>=1,C5,"") -> A-2245 | C5: A-2245 | D5: Vertical Tall <80 w/Gusset | E5: =VLOOKUP(C5,VLOOKUP!H:R,11,FALSE) -> 2 | F5: =E5 -> 2 | G5: =VLOOKUP(C5,lists!I:L,4,FALSE) -> 242.5 | H5: =G5*(1+$M$1) -> 242.5 | I5: =F5*O5 -> 136.5 | J5: =F5*G5 -> 485 | K5: =J5*(1+$M$1) -> 485 | L5: =ROUND(H5*(1+$M$2),2) -> 557.75 | M5: =F5*L5 -> 1115.5 | N5: =IFERROR((M5/K5)-1,"") -> 1.3 | O5: 68.25 | Q5: Revenue | R5: =M36 -> 8692.85 | S5: =SUM(M68:M125) -> 3374.08 | T5: =M48 -> 3548.9 | U5: =M176-S5 -> 2548.36 | V5: =M220 -> 1777.95 | W5: =SUM(R5:V5) -> 19942.14 | X5: =W5-R19 -> 16275.84 | Y5: =Y8*2 -> 19276.342 | Z5: =IF('Adventure Series Proposal (USA)'!H235="TBD",0) -> 0
B6: =IF(F6>=1,C6,"") -> A-2246 | C6: A-2246 | D6: Vertical Tall <80 w/Gussets, Rungs & Handles | E6: =VLOOKUP(C6,VLOOKUP!H:R,11,FALSE) -> 2 | F6: =E6 -> 2 | G6: =VLOOKUP(C6,lists!I:L,4,FALSE) -> 242.5 | H6: =G6*(1+$M$1) -> 242.5 | I6: =F6*O6 -> 134.58 | J6: =F6*G6 -> 485 | K6: =J6*(1+$M$1) -> 485 | L6: =ROUND(H6*(1+$M$2),2) -> 557.75 | M6: =F6*L6 -> 1115.5 | N6: =IFERROR((M6/K6)-1,"") -> 1.3 | O6: 67.29
B7: =IF(F7>=1,C7,"") | C7: A-2241 | D7: Corner Post <80 1-Way Weld Assembly | E7: =IF(VLOOKUP!E3="T Shape",2,"") | G7: =VLOOKUP(C7,lists!I:L,4,FALSE) -> 73 | H7: =G7*(1+$M$1) -> 73 | I7: =F7*O7 -> 0 | J7: =F7*G7 -> 0 | K7: =J7*(1+$M$1) -> 0 | L7: =ROUND(H7*(1+$M$2),2) -> 167.9 | M7: =F7*L7 -> 0 | N7: =IFERROR((M7/K7)-1,"") | O7: 11.886 | Q7: % of Revenue | R7: =R5/$W$5 -> 0.43590357 | S7: =S5/$W$5 -> 0.16919348 | T7: =T5/$W$5 -> 0.17795984 | U7: =U5/$W$5 -> 0.12778769 | V7: =V5/$W$5 -> 0.089155427 | W7: =W5/$W$5 -> 1
B8: =IF(F8>=1,C8,"") -> A-2242 | C8: A-2242 | D8: Corner Post <80 2-Way Weld Assembly | E8: =VLOOKUP(C8,VLOOKUP!H:R,11,FALSE) -> 4 | F8: =E8 -> 4 | G8: =VLOOKUP(C8,lists!I:L,4,FALSE) -> 76.5 | H8: =G8*(1+$M$1) -> 76.5 | I8: =F8*O8 -> 59.728 | J8: =F8*G8 -> 306 | K8: =J8*(1+$M$1) -> 306 | L8: =ROUND(H8*(1+$M$2),2) -> 175.95 | M8: =F8*L8 -> 703.8 | N8: =IFERROR((M8/K8)-1,"") -> 1.3 | O8: 14.932 | Q8: COGS | R8: =K36 -> 3779.5 | S8: =SUM(J68:J125) -> 2332.9 | T8: =K48 -> 1543 | U8: =K176-S8 -> 1107.98 | V8: =K220 -> 874.791 | W8: =SUM(R8:V8) -> 9638.171 | X8: =W8 -> 9638.171 | Y8: =W8 -> 9638.171 | Z8: =Z5 -> 0
B9: =IF(F9>=1,C9,"") | C9: A-2243 | D9: Corner Post <80 3-Way Weld Assembly | E9: =VLOOKUP(C9,VLOOKUP!H:R,11,FALSE) -> 0 | F9: =E9 -> 0 | G9: =VLOOKUP(C9,lists!I:L,4,FALSE) -> 97 | H9: =G9*(1+$M$1) -> 97 | I9: =F9*O9 -> 0 | J9: =F9*G9 -> 0 | K9: =J9*(1+$M$1) -> 0 | L9: =ROUND(H9*(1+$M$2),2) -> 223.1 | M9: =F9*L9 -> 0 | N9: =IFERROR((M9/K9)-1,"") | O9: 17.979 | Q9: % of COGS | R9: =R8/$W$8 -> 0.39213872 | S9: =S8/$W$8 -> 0.242048 | T9: =T8/$W$8 -> 0.16009262 | U9: =U8/$W$8 -> 0.1149575 | V9: =V8/$W$8 -> 0.090763175 | W9: =W8/$W$8 -> 1
B10: =IF(F10>=1,C10,"") | C10: A-2244 | D10: Corner Post <80 4-Way Weld Assembly | E10: =VLOOKUP(C10,VLOOKUP!H:R,11,FALSE) -> 0 | F10: =E10 -> 0 | G10: =VLOOKUP(C10,lists!I:L,4,FALSE) -> 101 | H10: =G10*(1+$M$1) -> 101 | I10: =F10*O10 -> 0 | J10: =F10*G10 -> 0 | K10: =J10*(1+$M$1) -> 0 | L10: =ROUND(H10*(1+$M$2),2) -> 232.3 | M10: =F10*L10 -> 0 | N10: =IFERROR((M10/K10)-1,"") | O10: 21.025 | Q10: Gross Margin | R10: =R5/R8 -> 2.3 | S10: =S5/S8 -> 1.4463029 | T10: =IFERROR(T5/T8,0) -> 2.3 | U10: =U5/U8 -> 2.3000054 | V10: =V5/V8 -> 2.0324283 | W10: =W5-W8 -> 10303.969 | X10: =X5-X8 -> 6637.669 | Y10: =Y5-Y8 -> 9638.171 | Z10: =Z5-Z8 -> 0
C11: A-2022 | D11: Corner Post Multi-Level 1-Way Weld Assembly | G11: 72.5 | H11: =G11*(1+$M$1) -> 72.5 | I11: =F11*O11 -> 0 | J11: =F11*G11 -> 0 | K11: =J11*(1+$M$1) -> 0 | L11: =ROUND(H11*(1+$M$2),2) -> 166.75 | M11: =F11*L11 -> 0 | N11: =IFERROR((M11/K11)-1,"") | O11: 14.932 | Q11: Gross Margin % | W11: =(W5/W8)-1 -> 1.0690793 | X11: =(X5/X8)-1 -> 0.68868554 | Y11: =(Y5/Y8)-1 -> 1 | Z11: =(Z5/Z8)-1 -> #DIV/0!
B12: =IF(F12>=1,C12,"") -> A-2225 | C12: A-2225 | D12: Mid Span 1-Way Saddle Alt Weld Assembly | E12: =VLOOKUP(C12,VLOOKUP!H:R,11,FALSE) -> 4 | F12: =E12 -> 4 | G12: =VLOOKUP(C12,lists!I:L,4,FALSE) -> 46 | H12: =G12*(1+$M$1) -> 46 | I12: =F12*O12 -> 25.84 | J12: =F12*G12 -> 184 | K12: =J12*(1+$M$1) -> 184 | L12: =ROUND(H12*(1+$M$2),2) -> 105.8 | M12: =F12*L12 -> 423.2 | N12: =IFERROR((M12/K12)-1,"") -> 1.3 | O12: 6.46 | Q12: Net Margin % | W12: =1-(W8/W5) -> 0.51669324 | X12: =1-(X8/X5) -> 0.40782344 | Y12: =1-(Y8/Y5) -> 0.5 | Z12: =1-(Z8/Z5) -> #DIV/0!
B13: =IF(F13>=1,C13,"") -> P-2531 | C13: P-2531 | D13: Ladder Leg Footless | E13: =F13 -> 2 | F13: =IF(VLOOKUP!E7>0,VLOOKUP!E7,0) -> 2 | G13: =VLOOKUP(C13,lists!I:L,4,FALSE) -> 97.5 | H13: =G13*(1+$M$1) -> 97.5 | I13: =F13*O13 -> 61.82 | J13: =F13*G13 -> 195 | K13: =J13*(1+$M$1) -> 195 | L13: =ROUND(H13*(1+$M$2),2) -> 224.25 | M13: =F13*L13 -> 448.5 | N13: =IFERROR((M13/K13)-1,"") -> 1.3 | O13: 30.91 | Q13: Delta | W13: =W12-0.5 -> 0.016693244 | X13: =X12-0.5 -> -0.092176564 | Y13: =Y12-0.5 -> 0
B14: =IF(F14>=1,C14,"") -> A-2253 | C14: A-2253 | D14: Single Leg Inner Ladder Sleeve Footless Weld Assembly | E14: =VLOOKUP(C14,VLOOKUP!H:R,11,FALSE) -> 2 | F14: =E14 -> 2 | G14: =VLOOKUP(C14,lists!I:L,4,FALSE) -> 65.5 | H14: =G14*(1+$M$1) -> 65.5 | I14: =F14*O14 -> 8.98 | J14: =F14*G14 -> 131 | K14: =J14*(1+$M$1) -> 131 | L14: =ROUND(H14*(1+$M$2),2) -> 150.65 | M14: =F14*L14 -> 301.3 | N14: =IFERROR((M14/K14)-1,"") -> 1.3 | O14: 4.49 | W14: $ Margin over 50% | Y14: =X10-Y10 -> -3000.502
B15: =IF(F15>=1,C15,"") | C15: A-2248 | D15: Double Leg Inner Ladder Sleeve | E15: =VLOOKUP(C15,VLOOKUP!H:R,11,FALSE) -> 0 | F15: =E15 -> 0 | G15: =VLOOKUP(C15,lists!I:L,4,FALSE) -> 79 | H15: =G15*(1+$M$1) -> 79 | I15: =F15*O15 -> 0 | J15: =F15*G15 -> 0 | K15: =J15*(1+$M$1) -> 0 | L15: =ROUND(H15*(1+$M$2),2) -> 181.7 | M15: =F15*L15 -> 0 | N15: =IFERROR((M15/K15)-1,"") | O15: 10.51 | W15: % Margin over 50% | Y15: =X11-Y11 -> -0.31131446
B16: =IF(F16>=1,C16,"") | C16: P-2545 | D16: 5' Full Bay HSS Member Alt w/ Logo | E16: =VLOOKUP(C16,VLOOKUP!H:R,11,FALSE) -> 0 | F16: =E16 -> 0 | G16: =VLOOKUP(C16,lists!I:L,4,FALSE) -> 150 | H16: =G16*(1+$M$1) -> 150 | I16: =F16*O16 -> 0 | J16: =F16*G16 -> 0 | K16: =J16*(1+$M$1) -> 0 | L16: =ROUND(H16*(1+$M$2),2) -> 345 | M16: =F16*L16 -> 0 | N16: =IFERROR((M16/K16)-1,"") | O16: 30
B17: =IF(F17>=1,C17,"") | C17: P-2206 | D17: 6' Full Bay HSS Member Alt w/ Logo | E17: =VLOOKUP(C17,VLOOKUP!H:R,11,FALSE) -> 0 | F17: =E17 -> 0 | G17: =VLOOKUP(C17,lists!I:L,4,FALSE) -> 150 | H17: =G17*(1+$M$1) -> 150 | I17: =F17*O17 -> 0 | J17: =F17*G17 -> 0 | K17: =J17*(1+$M$1) -> 0 | L17: =ROUND(H17*(1+$M$2),2) -> 345 | M17: =F17*L17 -> 0 | N17: =IFERROR((M17/K17)-1,"") | O17: 35.8
B18: =IF(F18>=1,C18,"") | C18: P-2207 | D18: 7' Full Bay HSS Member Alt w/ Logo | E18: =VLOOKUP(C18,VLOOKUP!H:R,11,FALSE) -> 0 | F18: 0 | G18: =VLOOKUP(C18,lists!I:L,4,FALSE) -> 150 | H18: =G18*(1+$M$1) -> 150 | I18: =F18*O18 -> 0 | J18: =F18*G18 -> 0 | K18: =J18*(1+$M$1) -> 0 | L18: =ROUND(H18*(1+$M$2),2) -> 345 | M18: =F18*L18 -> 0 | N18: =IFERROR((M18/K18)-1,"") | O18: 42.5 | R18: Discount Offered | S18: Discount Offered % | U18: Discount % | V18: Discount $
B19: =IF(F19>=1,C19,"") | C19: A-2408 | D19: 8' Half Bay <80 HSS Member w/Splices & HDWE | E19: =VLOOKUP(C19,VLOOKUP!H:R,11,FALSE) -> 0 | F19: =E19 -> 0 | G19: =VLOOKUP(C19,lists!I:L,4,FALSE) -> 190 | H19: =G19*(1+$M$1) -> 190 | I19: =F19*O19 -> 0 | J19: =F19*G19 -> 0 | K19: =J19*(1+$M$1) -> 0 | L19: =ROUND(H19*(1+$M$2),2) -> 437 | M19: =F19*L19 -> 0 | N19: =IFERROR((M19/K19)-1,"") | O19: 49.26 | R19: 3666.3 | S19: =R19/W5 -> 0.18384687 | U19: 0 | V19: =W5*U19 -> 0
B20: =IF(F20>=1,C20,"") | C20: A-2409 | D20: 9' Half Bay <80 HSS Member w/Splices & HDWE | E20: =VLOOKUP(C20,VLOOKUP!H:R,11,FALSE) -> 0 | F20: 0 | G20: =VLOOKUP(C20,lists!I:L,4,FALSE) -> 200 | H20: =G20*(1+$M$1) -> 200 | I20: =F20*O20 -> 0 | J20: =F20*G20 -> 0 | K20: =J20*(1+$M$1) -> 0 | L20: =ROUND(H20*(1+$M$2),2) -> 460 | M20: =F20*L20 -> 0 | N20: =IFERROR((M20/K20)-1,"") | O20: 56.01
B21: =IF(F21>=1,C21,"") -> A-2410 | C21: A-2410 | D21: 10' Half Bay <80 HSS Member w/Splices & HDWE | E21: =VLOOKUP(C21,VLOOKUP!H:R,11,FALSE) -> 4 | F21: =E21 -> 4 | G21: =VLOOKUP(C21,lists!I:L,4,FALSE) -> 200 | H21: =G21*(1+$M$1) -> 200 | I21: =F21*O21 -> 271.6 | J21: =F21*G21 -> 800 | K21: =J21*(1+$M$1) -> 800 | L21: =ROUND(H21*(1+$M$2),2) -> 460 | M21: =F21*L21 -> 1840 | N21: =IFERROR((M21/K21)-1,"") -> 1.3 | O21: 67.9 | R21: Expiration Date | W21: 28277.23 | X21: 3931.2
B22: =IF(F22>=1,C22,"") -> P-2330 | C22: P-2330 | D22: Monkey Bar / Ladder Rungs w/ 4 Threaded Holes | E22: =VLOOKUP(C22,VLOOKUP!H:R,11,FALSE) -> 19 | F22: =E22 -> 19 | G22: =VLOOKUP(C22,lists!I:L,4,FALSE) -> 20.5 | H22: =G22*(1+$M$1) -> 20.5 | I22: =F22*O22 -> 45.41 | J22: =F22*G22 -> 389.5 | K22: =J22*(1+$M$1) -> 389.5 | L22: =ROUND(H22*(1+$M$2),2) -> 47.15 | M22: =F22*L22 -> 895.85 | N22: =IFERROR((M22/K22)-1,"") -> 1.3 | O22: 2.39 | R22: =TODAY()+6 -> 46231 | W22: 27892.38 | X22: 3510
B23: =IF(F23>=1,C23,"") | C23: P-2216 | D23: 6' Full Bay Monkey Bar HSS Member w/ Logo | E23: =VLOOKUP(C23,VLOOKUP!H:R,11,FALSE) -> 0 | F23: =E23 -> 0 | G23: =VLOOKUP(C23,lists!I:L,4,FALSE) -> 150 | H23: =G23*(1+$M$1) -> 150 | I23: =F23*O23 -> 0 | J23: =F23*G23 -> 0 | K23: =J23*(1+$M$1) -> 0 | L23: =ROUND(H23*(1+$M$2),2) -> 345 | M23: =F23*L23 -> 0 | N23: =IFERROR((M23/K23)-1,"") | O23: 34.85 | W23: =W21-W22 -> 384.85 | X23: =X21-X22 -> 421.2
B24: =IF(F24>=1,C24,"") | C24: P-2217 | D24: 7' Full Bay Monkey Bar HSS Member w/ Logo | E24: =VLOOKUP(C24,VLOOKUP!H:R,11,FALSE) -> 0 | F24: =E24 -> 0 | G24: =VLOOKUP(C24,lists!I:L,4,FALSE) -> 150 | H24: =G24*(1+$M$1) -> 150 | I24: =F24*O24 -> 0 | J24: =F24*G24 -> 0 | K24: =J24*(1+$M$1) -> 0 | L24: =ROUND(H24*(1+$M$2),2) -> 345 | M24: =F24*L24 -> 0 | N24: =IFERROR((M24/K24)-1,"") | O24: 41.41 | R24: MAX Discount | S24: MAX DISCOUNT %
B25: =IF(F25>=1,C25,"") | C25: A-2418 | D25: 8' Half Bay Monkey Bar HSS Member w/ Logo | E25: =VLOOKUP(C25,VLOOKUP!H:R,11,FALSE) -> 0 | F25: =E25 -> 0 | G25: =VLOOKUP(C25,lists!I:L,4,FALSE) -> 190 | H25: =G25*(1+$M$1) -> 190 | I25: =F25*O25 -> 0 | J25: =F25*G25 -> 0 | K25: =J25*(1+$M$1) -> 0 | L25: =ROUND(H25*(1+$M$2),2) -> 437 | M25: =F25*L25 -> 0 | N25: =IFERROR((M25/K25)-1,"") | O25: 47.97 | Q25: 100% of MAX | R25: =W5-Y5 -> 665.798 | S25: =(R25/W5) -> 0.033386487
B26: =IF(F26>=1,C26,"") | C26: A-2419 | D26: 9' Half Bay <80 Monkey Bar HSS w/Splices & HDWE | E26: =VLOOKUP(C26,VLOOKUP!H:R,11,FALSE) -> 0 | F26: =E26 -> 0 | G26: =VLOOKUP(C26,lists!I:L,4,FALSE) -> 200 | H26: =G26*(1+$M$1) -> 200 | I26: =F26*O26 -> 0 | J26: =F26*G26 -> 0 | K26: =J26*(1+$M$1) -> 0 | L26: =ROUND(H26*(1+$M$2),2) -> 460 | M26: =F26*L26 -> 0 | N26: =IFERROR((M26/K26)-1,"") | O26: 54.53 | Q26: 75% of MAX | R26: =R25*0.75 -> 499.3485 | S26: =R26/W5 -> 0.025039865
B27: =IF(F27>=1,C27,"") -> A-2420 | C27: A-2420 | D27: 10' Half Bay <80 Monkey Bar HSS w/Splices & HDWE | E27: =VLOOKUP(C27,VLOOKUP!H:R,11,FALSE) -> 2 | F27: =E27 -> 2 | G27: =VLOOKUP(C27,lists!I:L,4,FALSE) -> 200 | H27: =G27*(1+$M$1) -> 200 | I27: =F27*O27 -> 132.44 | J27: =F27*G27 -> 400 | K27: =J27*(1+$M$1) -> 400 | L27: =ROUND(H27*(1+$M$2),2) -> 460 | M27: =F27*L27 -> 920 | N27: =IFERROR((M27/K27)-1,"") -> 1.3 | O27: 66.22 | Q27: 50% of MAX | R27: =R25*0.5 -> 332.899 | S27: =R27/W5 -> 0.016693244
B28: =IF(F28>=1,C28,"") | C28: P-2024 | D28: Zip Line HSS Tube | E28: =IF(VLOOKUP!E17="Yes",2,0) -> 0 | F28: =E28 -> 0 | G28: =VLOOKUP(C28,lists!I:L,4,FALSE) -> 20 | H28: =G28*(1+$M$1) -> 20 | I28: =F28*O28 -> 0 | J28: =F28*G28 -> 0 | K28: =J28*(1+$M$1) -> 0 | L28: =ROUND(H28*(1.5),2) -> 30 | M28: =F28*L28 -> 0 | N28: =IFERROR((M28/K28)-1,"") | O28: 5.63 | Q28: 25% of MAX | R28: =R25*0.25 -> 166.4495 | S28: =R28/W5 -> 0.0083466218
B29: =IF(F29>=1,C29,"") | C29: A-2530 | D29: Zip Line Collar | E29: =IF(VLOOKUP!E17="Yes",4,0) -> 0 | F29: =E29 -> 0 | G29: =VLOOKUP(C29,lists!I:L,4,FALSE) -> 53 | H29: =G29*(1+$M$1) -> 53 | I29: =F29*O29 -> 0 | J29: =F29*G29 -> 0 | K29: =J29*(1+$M$1) -> 0 | L29: =ROUND(H29*(1.5),2) -> 79.5 | M29: =F29*L29 -> 0 | N29: =IFERROR((M29/K29)-1,"") | O29: 4.5
B30: =IF(F30>=1,C30,"") -> P-2124 | C30: P-2124 | D30: Quick Shift Saddle Bracket™ | E30: =VLOOKUP!E43 -> 4 | F30: =E30 -> 4 | G30: =VLOOKUP(C30,lists!I:L,4,FALSE) -> 51 | H30: =G30*(1+$M$1) -> 51 | I30: =F30*O30 -> 19.32 | J30: =F30*G30 -> 204 | K30: =J30*(1+$M$1) -> 204 | L30: =ROUND(H30*(1+$M$2),2) -> 117.3 | M30: =F30*L30 -> 469.2 | N30: =IFERROR((M30/K30)-1,"") -> 1.3 | O30: 4.83
B31: =IF(F31>=1,C31,"") -> P-2028 | C31: P-2028 | D31: Base Plate Shield | E31: =VLOOKUP(C31,VLOOKUP!H:R,11,FALSE) -> 8 | F31: =E31 -> 8 | G31: =VLOOKUP(C31,lists!I:L,4,FALSE) -> 25 | H31: =G31*(1+$M$1) -> 25 | I31: =F31*O31 -> 22.48 | J31: =F31*G31 -> 200 | K31: =J31*(1+$M$1) -> 200 | L31: =ROUND(H31*(1+$M$2),2) -> 57.5 | M31: =F31*L31 -> 460 | N31: =IFERROR((M31/K31)-1,"") -> 1.3 | O31: 2.81
B32: =IF(F32>=1,C32,"") | C32: P-2500 | D32: Safety First Climbing Shield (48" x 18") | E32: =IF(VLOOKUP!E26="Yes",1,0) -> 0 | F32: =E32 -> 0 | G32: =VLOOKUP(C32,lists!I:L,4,FALSE) -> 52 | H32: =G32*(1+$M$1) -> 52 | I32: =F32*O32 -> 0 | J32: =F32*G32 -> 0 | K32: =J32*(1+$M$1) -> 0 | L32: =ROUND(H32*(1+$M$2),2) -> 119.6 | M32: =F32*L32 -> 0 | N32: =IFERROR((M32/K32)-1,"") | O32: 24.5 | R32: Repeat Customer Discount
B33: =IF(F33>=1,C33,"") | C33: P-2501 | D33: Safety First Ladder Climbing Shield (90° Angle) | E33: =IF(Discovery!C37>8.1,VLOOKUP!E6*2,0) -> 0 | F33: =E33 -> 0 | G33: =VLOOKUP(C33,lists!I:L,4,FALSE) -> 52 | H33: =G33*(1+$M$1) -> 52 | I33: 22 | J33: =F33*G33 -> 0 | K33: =J33*(1+$M$1) -> 0 | L33: =ROUND(H33*(1+$M$2),2) -> 119.6 | M33: =F33*L33 -> 0 | N33: =IFERROR((M33/K33)-1,"") | O33: 22 | R33: 0.15 | S33: =W5*R33 -> 2991.321
B34: =IF(F34>=1,C34,"") | C34: P-2502 | D34: Safety First Ladder Climbing Shield (50° Angle) | E34: =IF(VLOOKUP!E35="Yes",VLOOKUP!E7,0) -> 0 | F34: =E34 -> 0 | G34: =VLOOKUP(C34,lists!I:L,4,FALSE) -> 52 | H34: =G34*(1+$M$1) -> 52 | I34: 23 | J34: =F34*G34 -> 0 | K34: =J34*(1+$M$1) -> 0 | L34: =ROUND(H34*(1+$M$2),2) -> 119.6 | M34: =F34*L34 -> 0 | N34: =IFERROR((M34/K34)-1,"") | O34: 22.3
B35: =IF(F35>=1,C35,"") | C35: P-1032 | D35: 4.5' Full Bay HSS Member Alt w/Logo | E35: =VLOOKUP(C35,VLOOKUP!H:R,10,FALSE) -> 0 | F35: =E35 -> 0 | G35: 155 | H35: =G35*(1+$M$1) -> 155 | I35: =F35*O35 -> 0 | J35: =F35*G35 -> 0 | K35: =J35*(1+$M$1) -> 0 | L35: =ROUND(H35*(1+$M$2),2) -> 356.5 | M35: =F35*L35 -> 0 | N35: =IFERROR((M35/K35)-1,"") | O35: 61.1
E36: =SUM(E5:E35) -> 53 | F36: =SUM(F5:F35) -> 53 | J36: SUBTOTAL | K36: =SUM(J5:J35) -> 3779.5 | L36: SUBTOTAL | M36: =SUM(M5:M35) -> 8692.85
A38: TROLLEY PARTS
B39: =IF(F39>=1,C39,"") -> P-2018 | C39: P-2018 | D39: Trolley Bar | E39: =VLOOKUP(C39,VLOOKUP!H:R,11,FALSE) -> 1 | F39: =E39 -> 1 | G39: =VLOOKUP(C39,[1]lists!I:L,4,FALSE) -> 14 | H39: =G39*(1+$M$1) -> 14 | I39: =F39*O39 -> 2.27 | J39: =F39*G39 -> 14 | K39: =J39*(1+$M$1) -> 14 | L39: =ROUND(H39*(1+$M$2),2) -> 32.2 | M39: =F39*L39 -> 32.2 | N39: =IFERROR((M39/K39)-1,"") -> 1.3 | O39: 2.27
B40: =IF(F40>=1,C40,"") -> P-2025 | C40: P-2025 | D40: Trolley Bar Plate | E40: =VLOOKUP(C40,VLOOKUP!H:R,11,FALSE) -> 2 | F40: =E40 -> 2 | G40: =VLOOKUP(C40,[1]lists!I:L,4,FALSE) -> 12 | H40: =G40*(1+$M$1) -> 12 | I40: =F40*O40 -> 0.594 | J40: =F40*G40 -> 24 | K40: =J40*(1+$M$1) -> 24 | L40: =ROUND(H40*(1+$M$2),2) -> 27.6 | M40: =F40*L40 -> 55.2 | N40: =IFERROR((M40/K40)-1,"") -> 1.3 | O40: 0.297
B41: =IF(F41>=1,"SSG-TR-A10","") | C41: TR2000-A10 | D41: 10' Aluminum Enclosed Rail 550lbs. Max Weight | E41: =VLOOKUP(C41,VLOOKUP!H:R,11,FALSE) -> 0 | F41: =E41 -> 0 | G41: =VLOOKUP(C41,[1]lists!I:M,5,FALSE) -> 215.1 | H41: =G41*(1+$M$1) -> 215.1 | I41: =F41*O41 -> 0 | J41: =F41*G41 -> 0 | K41: =J41*(1+$M$1) -> 0 | L41: =ROUND(H41*(1+$M$2),2) -> 494.73 | M41: =F41*L41 -> 0 | N41: =IFERROR((M41/K41)-1,"") | O41: 26.17
...

Sheet Goldberg Order Details
A4: SUMMIT PRODUCT ORDER FORM
A5: Job: | B5: =Discovery!B3 -> Soar Autism Center - South Fort Collins
A6: Submission Date: | B6: =TODAY() -> 46225
A7: Shipment Details: | B7: =Discovery!B2 -> Tyler Galiotto
B8: =Discovery!B3 -> Soar Autism Center - South Fort Collins
B9: =Discovery!B7 -> 3801 Automation Way
B10: =Discovery!B8&" "&Discovery!B9 -> Fort Collins, CO 80525
A11: Phone: | B11: =Discovery!B11 -> 5203895979
A12: Email: | B12: =Discovery!B12
A13: Total Steel Weight: | B13: =CEILING(SUM(E18:E45)+5,10)&" (STEEL) LBS"&IF(Calcs!F47>0," + "&CEILING(SUM(Calcs!I41:I47),5)&" (TROLLEY) LBS"&" ="&(CEILING(SUM(E18:E45)+5,10)+CEILING(SUM(Calcs!I41:I47),5))&" TOTAL","")&" **DOESN'T INCLUDE HARDWARE OR CRATING**" -> 930 (STEEL) LBS + 70 (TROLLEY) LBS =1000 TOTAL **DOESN'T INCLUDE HARDWARE OR CRATING**
A14: Estimated Shipment Quote: | B14: =Discovery!B19 -> TBD
A15: Delivery Type: | B15: Lift Gate
A16: Powder Coat Brand: | B16: =Discovery!B44 -> Cardinal
A17: LINE # | B17: DESCRIPTION | C17: QTY PER UNIT | D17: Powder Color | E17: Weight (lbs) | F17: PRICE EACH | G17: TOTAL PRICE PER UNIT
A18: A-2245 | B18: =VLOOKUP(A18,Calcs!C5:D35,2,FALSE) -> Vertical Tall <80 w/Gusset | C18: =VLOOKUP(A18,Calcs!$C$5:$F$260,4,FALSE) -> 2 | D18: =Discovery!B47 -> CHANGEME | E18: =(VLOOKUP(A18,Calcs!$C$5:$O$298,13,FALSE))*C18 -> 136.5 | F18: =VLOOKUP(A18,lists!I:L,4,FALSE) -> 242.5 | G18: =C18*F18 -> 485
A19: A-2246 | B19: =VLOOKUP(A19,Calcs!C6:D40,2,FALSE) -> Vertical Tall <80 w/Gussets, Rungs & Handles | C19: =VLOOKUP(A19,Calcs!$C$5:$F$260,4,FALSE) -> 2 | D19: =Discovery!B47 -> CHANGEME | E19: =(VLOOKUP(A19,Calcs!$C$5:$O$298,13,FALSE))*C19 -> 134.58 | F19: =VLOOKUP(A19,lists!I:L,4,FALSE) -> 242.5 | G19: =C19*F19 -> 485
A20: A-2241 | B20: =VLOOKUP(A20,Calcs!C7:D42,2,FALSE) -> Corner Post <80 1-Way Weld Assembly | C20: =VLOOKUP(A20,Calcs!$C$5:$F$260,4,FALSE) -> 0 | D20: =Discovery!B48 -> CHANGEME | E20: =(VLOOKUP(A20,Calcs!$C$5:$O$298,13,FALSE))*C20 -> 0 | F20: =VLOOKUP(A20,lists!I:L,4,FALSE) -> 73 | G20: =C20*F20 -> 0
A21: A-2242 | B21: =VLOOKUP(A21,Calcs!C8:D43,2,FALSE) -> Corner Post <80 2-Way Weld Assembly | C21: =VLOOKUP(A21,Calcs!$C$5:$F$260,4,FALSE) -> 4 | D21: =Discovery!B48 -> CHANGEME | E21: =(VLOOKUP(A21,Calcs!$C$5:$O$298,13,FALSE))*C21 -> 59.728 | F21: =VLOOKUP(A21,lists!I:L,4,FALSE) -> 76.5 | G21: =C21*F21 -> 306
A22: A-2243 | B22: =VLOOKUP(A22,Calcs!C9:D44,2,FALSE) -> Corner Post <80 3-Way Weld Assembly | C22: =VLOOKUP(A22,Calcs!$C$5:$F$260,4,FALSE) -> 0 | D22: =Discovery!B48 -> CHANGEME | E22: =(VLOOKUP(A22,Calcs!$C$5:$O$298,13,FALSE))*C22 -> 0 | F22: =VLOOKUP(A22,lists!I:L,4,FALSE) -> 97 | G22: =C22*F22 -> 0
A23: A-2244 | B23: =VLOOKUP(A23,Calcs!C10:D45,2,FALSE) -> Corner Post <80 4-Way Weld Assembly | C23: =VLOOKUP(A23,Calcs!$C$5:$F$260,4,FALSE) -> 0 | D23: =Discovery!B48 -> CHANGEME | E23: =(VLOOKUP(A23,Calcs!$C$5:$O$298,13,FALSE))*C23 -> 0 | F23: =VLOOKUP(A23,lists!I:L,4,FALSE) -> 101 | G23: =C23*F23 -> 0
A24: A-2225 | B24: =VLOOKUP(A24,Calcs!C12:D46,2,FALSE) -> Mid Span 1-Way Saddle Alt Weld Assembly | C24: =VLOOKUP(A24,Calcs!$C$5:$F$260,4,FALSE) -> 4 | D24: =Discovery!B48 -> CHANGEME | E24: =(VLOOKUP(A24,Calcs!$C$5:$O$298,13,FALSE))*C24 -> 25.84 | F24: =VLOOKUP(A24,lists!I:L,4,FALSE) -> 46 | G24: =C24*F24 -> 184
A25: P-2531 | B25: =VLOOKUP(A25,Calcs!C13:D47,2,FALSE) -> Ladder Leg Footless | C25: =VLOOKUP(A25,Calcs!$C$5:$F$260,4,FALSE) -> 2 | D25: =Discovery!B49 -> CHANGEME | E25: =(VLOOKUP(A25,Calcs!$C$5:$O$298,13,FALSE))*C25 -> 61.82 | F25: =VLOOKUP(A25,lists!I:L,4,FALSE) -> 97.5 | G25: =C25*F25 -> 195
A26: A-2253 | B26: =VLOOKUP(A26,Calcs!C14:D59,2,FALSE) -> Single Leg Inner Ladder Sleeve Footless Weld Assembly | C26: =VLOOKUP(A26,Calcs!$C$5:$F$260,4,FALSE) -> 2 | D26: =Discovery!B49 -> CHANGEME | E26: =(VLOOKUP(A26,Calcs!$C$5:$O$298,13,FALSE))*C26 -> 8.98 | F26: =VLOOKUP(A26,lists!I:L,4,FALSE) -> 65.5 | G26: =C26*F26 -> 131
A27: A-2248 | B27: =VLOOKUP(A27,Calcs!C15:D60,2,FALSE) -> Double Leg Inner Ladder Sleeve | C27: =VLOOKUP(A27,Calcs!$C$5:$F$260,4,FALSE) -> 0 | D27: =Discovery!B49 -> CHANGEME | E27: =(VLOOKUP(A27,Calcs!$C$5:$O$298,13,FALSE))*C27 -> 0 | F27: =VLOOKUP(A27,lists!I:L,4,FALSE) -> 79 | G27: =C27*F27 -> 0
A28: P-2206 | B28: 6' Full Bay HSS Member Alt W/Logo | C28: =VLOOKUP(A28,Calcs!$C$5:$F$260,4,FALSE) -> 0 | D28: =Discovery!B48 -> CHANGEME | E28: =(VLOOKUP(A28,Calcs!$C$5:$O$298,13,FALSE))*C28 -> 0 | F28: =VLOOKUP(A28,lists!I:L,4,FALSE) -> 150 | G28: =C28*F28 -> 0
A29: p-2207 | B29: 7' Full Bay HSS Member Alt w/ Logo | C29: =VLOOKUP(A29,Calcs!$C$5:$F$260,4,FALSE) -> 0 | D29: =Discovery!B48 -> CHANGEME | E29: =(VLOOKUP(A29,Calcs!$C$5:$O$298,13,FALSE))*C29 -> 0 | F29: =VLOOKUP(A29,lists!I:L,4,FALSE) -> 150 | G29: =C29*F29 -> 0
A30: A-2408 | B30: =VLOOKUP(A30,Calcs!C19:D61,2,FALSE) -> 8' Half Bay <80 HSS Member w/Splices & HDWE | C30: =VLOOKUP(A30,Calcs!$C$5:$F$260,4,FALSE) -> 0 | D30: =Discovery!B48 -> CHANGEME | E30: =(VLOOKUP(A30,Calcs!$C$5:$O$298,13,FALSE))*C30 -> 0 | F30: =VLOOKUP(A30,lists!I:L,4,FALSE) -> 190 | G30: =C30*F30 -> 0
A31: A-2409 | B31: =VLOOKUP(A31,Calcs!C20:D68,2,FALSE) -> 9' Half Bay <80 HSS Member w/Splices & HDWE | C31: =VLOOKUP(A31,Calcs!$C$5:$F$260,4,FALSE) -> 0 | D31: =Discovery!B48 -> CHANGEME | E31: =(VLOOKUP(A31,Calcs!$C$5:$O$298,13,FALSE))*C31 -> 0 | F31: =VLOOKUP(A31,lists!I:L,4,FALSE) -> 200 | G31: =C31*F31 -> 0
A32: A-2410 | B32: =VLOOKUP(A32,Calcs!C21:D71,2,FALSE) -> 10' Half Bay <80 HSS Member w/Splices & HDWE | C32: =VLOOKUP(A32,Calcs!$C$5:$F$260,4,FALSE) -> 4 | D32: =Discovery!B48 -> CHANGEME | E32: =(VLOOKUP(A32,Calcs!$C$5:$O$298,13,FALSE))*C32 -> 271.6 | F32: =VLOOKUP(A32,lists!I:L,4,FALSE) -> 200 | G32: =C32*F32 -> 800
A33: P-2330 | B33: =VLOOKUP(A33,Calcs!C22:D71,2,FALSE) -> Monkey Bar / Ladder Rungs w/ 4 Threaded Holes | C33: =VLOOKUP(A33,Calcs!$C$5:$F$260,4,FALSE) -> 19 | D33: =Discovery!B49 -> CHANGEME | E33: =(VLOOKUP(A33,Calcs!$C$5:$O$298,13,FALSE))*C33 -> 45.41 | F33: =VLOOKUP(A33,lists!I:L,4,FALSE) -> 20.5 | G33: =C33*F33 -> 389.5
A34: A-2418 | B34: =VLOOKUP(A34,Calcs!C25:D71,2,FALSE) -> 8' Half Bay Monkey Bar HSS Member w/ Logo | C34: =VLOOKUP(A34,Calcs!$C$5:$F$260,4,FALSE) -> 0 | D34: =Discovery!B48 -> CHANGEME | E34: =(VLOOKUP(A34,Calcs!$C$5:$O$298,13,FALSE))*C34 -> 0 | F34: =VLOOKUP(A34,lists!I:L,4,FALSE) -> 190 | G34: =C34*F34 -> 0
A35: A-2419 | B35: =VLOOKUP(A35,Calcs!C26:D104,2,FALSE) -> 9' Half Bay <80 Monkey Bar HSS w/Splices & HDWE | C35: =VLOOKUP(A35,Calcs!$C$5:$F$260,4,FALSE) -> 0 | D35: =Discovery!B48 -> CHANGEME | E35: =(VLOOKUP(A35,Calcs!$C$5:$O$298,13,FALSE))*C35 -> 0 | F35: =VLOOKUP(A35,lists!I:L,4,FALSE) -> 200 | G35: =C35*F35 -> 0
A36: A-2420 | B36: =VLOOKUP(A36,Calcs!C27:D105,2,FALSE) -> 10' Half Bay <80 Monkey Bar HSS w/Splices & HDWE | C36: =VLOOKUP(A36,Calcs!$C$5:$F$260,4,FALSE) -> 2 | D36: =Discovery!B48 -> CHANGEME | E36: =(VLOOKUP(A36,Calcs!$C$5:$O$298,13,FALSE))*C36 -> 132.44 | F36: =VLOOKUP(A36,lists!I:L,4,FALSE) -> 200 | G36: =C36*F36 -> 400
A37: P-2024 | B37: =VLOOKUP(A37,Calcs!C28:D130,2,FALSE) -> Zip Line HSS Tube | C37: =VLOOKUP(A37,Calcs!$C$5:$F$260,4,FALSE) -> 0 | D37: =Discovery!B48 -> CHANGEME | E37: =(VLOOKUP(A37,Calcs!$C$5:$O$298,13,FALSE))*C37 -> 0 | F37: =VLOOKUP(A37,lists!I:L,4,FALSE) -> 20 | G37: =C37*F37 -> 0
A38: A-2530 | B38: ADVENTURE ZIPLINE COLLAR STIFFENER WELD ASSY | C38: =VLOOKUP(A38,Calcs!$C$5:$F$260,4,FALSE) -> 0 | D38: =Discovery!B48 -> CHANGEME | E38: =(VLOOKUP(A38,Calcs!$C$5:$O$298,13,FALSE))*C38 -> 0 | F38: =VLOOKUP(A38,lists!I:L,4,FALSE) -> 53 | G38: =C38*F38 -> 0
A39: P-2124 | B39: =VLOOKUP(A39,Calcs!C30:D132,2,FALSE) -> Quick Shift Saddle Bracket™ | C39: =VLOOKUP(A39,Calcs!$C$5:$F$260,4,FALSE) -> 4 | D39: =Discovery!B49 -> CHANGEME | E39: =(VLOOKUP(A39,Calcs!$C$5:$O$298,13,FALSE))*C39 -> 19.32 | F39: =VLOOKUP(A39,lists!I:L,4,FALSE) -> 51 | G39: =C39*F39 -> 204
A40: P-2028 | B40: =VLOOKUP(A40,Calcs!C31:D133,2,FALSE) -> Base Plate Shield | C40: =VLOOKUP(A40,Calcs!$C$5:$F$260,4,FALSE) -> 8 | D40: =Discovery!B47 -> CHANGEME | E40: =(VLOOKUP(A40,Calcs!$C$5:$O$298,13,FALSE))*C40 -> 22.48 | F40: =VLOOKUP(A40,lists!I:L,4,FALSE) -> 25 | G40: =C40*F40 -> 200
A41: P-2500 | B41: CLIMBING WALL SHIELD | C41: =VLOOKUP(A41,Calcs!$C$5:$F$260,4,FALSE) -> 0 | D41: =Discovery!B48 -> CHANGEME | E41: =(VLOOKUP(A41,Calcs!$C$5:$O$298,13,FALSE))*C41 -> 0 | F41: =VLOOKUP(A41,lists!I:L,4,FALSE) -> 52 | G41: =C41*F41 -> 0
A42: P-2501 | B42: LADDER TOP SHIELD 90 DEGREE | C42: =VLOOKUP(A42,Calcs!$C$5:$F$260,4,FALSE) -> 0 | D42: =Discovery!B48 -> CHANGEME | E42: =(VLOOKUP(A42,Calcs!$C$5:$O$298,13,FALSE))*C42 -> 0 | F42: =VLOOKUP(A42,lists!I:L,4,FALSE) -> 52 | G42: =C42*F42 -> 0
A43: P-2502 | B43: LADDER TOP SHIELD 50 DEGREE | C43: =VLOOKUP(A43,Calcs!$C$5:$F$260,4,FALSE) -> 0 | D43: =Discovery!B48 -> CHANGEME | E43: =(VLOOKUP(A43,Calcs!$C$5:$O$298,13,FALSE))*C43 -> 0 | F43: =VLOOKUP(A43,lists!I:L,4,FALSE) -> 52 | G43: =C43*F43 -> 0
...

Sheet Sensory Space Proposal
B1: Summit Sensory Gym | J1: PSF File Name | K1: =B10&" - PSF 73 - "&TEXT(H9,"MMDDYYYY") -> Soar Autism Center - South Fort Collins - PSF 73 - 07222026
B2: 6150 S Geneva Court | J2: Proposal File Name | K2: =B10&" - "&F9&" - "&TEXT(H9,"MMDDYYYY") -> Soar Autism Center - South Fort Collins - SENSORY-SS-260722-001 - 07222026
B3: Englewood, CO 80111
B4: Phone: 720-457-5500
B5: Fax: 720-242-8085
B6: Support@SummitSensory.com
B8: CUSTOMER INFO | F8: PROPOSAL | H8: DATE
B9: =Discovery!B2 -> Tyler Galiotto | F9: ="SENSORY-" & UPPER(LEFT(B10,1) & RIGHT(B10,1)) & "-" & TEXT(H9,"yymmdd") & "-" & TEXT( IF(AND(ISNUMBER(K11),K11>0), K11, COUNTIFS($B$10:B10,B10,$H$9:H9,H9) ), "000") -> SENSORY-SS-260722-001 | H9: =TODAY() -> 46225
B10: =Discovery!B3 -> Soar Autism Center - South Fort Collins | F10: PROJECT ID # | H10: VALID UNTIL
B11: =Discovery!B4 -> 3801 Automation Way | F11: ="SSG-"&Discovery!B13 -> SSG-12552093278 | H11: =H9+6 -> 46231 | J11: Proposal # Override | K11: 0
B12: =Discovery!B5&" "&Discovery!B6&" "&Discovery!B10 -> Fort Collins, CO 80525 United States
B14: PROPOSAL DETAILS
B15: SENSORY ROOM EQUIPMENT & SUPPLIES - ITEMIZED PRODUCT PROPOSAL
B18: DESCRIPTION | C18: ITEM # | D18: SKU | E18: PRODUCT NOTES | F18: QTY | G18: FREIGHT COST (USD) | H18: TOTAL COST (USD)
C19: 1 | G19: 0 | H19: =F19+G19 -> 0
C20: =C19+1 -> 2 | G20: 0 | H20: =F20+G20 -> 0
C21: =C20+1 -> 3 | G21: 0 | H21: =F21+G21 -> 0
C22: =C21+1 -> 4 | G22: 0 | H22: =F22+G22 -> 0
C23: =C22+1 -> 5 | G23: 0 | H23: =F23+G23 -> 0
C24: =C23+1 -> 6 | G24: 0 | H24: =F24+G24 -> 0
C25: =C24+1 -> 7 | G25: 0 | H25: =F25+G25 -> 0
C26: =C25+1 -> 8 | G26: 0 | H26: =F26+G26 -> 0
C27: =C26+1 -> 9 | G27: 0 | H27: =F27+G27 -> 0
C28: =C27+1 -> 10 | G28: 0 | H28: =F28+G28 -> 0
C29: =C28+1 -> 11 | G29: 0 | H29: =F29+G29 -> 0
C30: =C29+1 -> 12 | G30: 0 | H30: =F30+G30 -> 0
C31: =C30+1 -> 13 | G31: 0 | H31: =F31+G31 -> 0
... C195: =C194+1 -> 177 | G195: 0 | H195: =F195+G195 -> 0
F196: SUBTOTAL: | H196: =SUM(H19:H195) -> 0
F197: ESTIMATED TAXES: | H197: 0
F198: TOTAL PROPOSAL: | H198: =H196+H197 -> 0
B200: IMPORTANT PROPOSAL DETAILS: This proposal serves as a detailed estimate of the total cost for the products and services outlined and does not constitute an invoice. Once signed and returned, it becomes a binding agreement, confirming acceptance of the order and associated payment terms. A 50% deposit is required to initiate production, with the remaining balance due prior to shipment. The signed proposal may be returned by mail or fax using the contact information provided above. For payments made by credit card, a 3.5% processing fee will be added to the total amount.
B202: CRATING & FREIGHT FEES: Final crating and freight charges will be calculated and invoiced at the time of shipment based on the actual costs incurred and the rates in effect at that time. Summit makes no representations or warranties, express or implied, regarding the availability or stability of crating costs or freight rates prior to shipment, and Buyer acknowledges and agrees that such charges may increase or decrease between the date of proposal and the shipment date.
B205: Customer Acceptance
B210: Signature | D210: Printed Name | G210: Date
B212: If you have any questions, please feel free to contact Bryan Shepherd at 720-457-5500 / Bryan@SummitSensory.com

Sheet Adventure Series Proposal (USA)
B1: Summit Sensory Gym | J1: PSF File Name | K1: =B10&" - "&VLOOKUP!F1&" - PSFv73 - "&TEXT(H9,"MMDDYYYY") -> Soar Autism Center - South Fort Collins - SQ-2MBL2T-10x10 - PSFv73 - 07222026
B2: 6150 S Geneva Court | J2: Proposal File Name | K2: =B10&" - "&VLOOKUP!F1&" - Proposal "&F9&" - "&TEXT(H9,"MMDDYYYY") -> Soar Autism Center - South Fort Collins - SQ-2MBL2T-10x10 - Proposal ADV-SS-260722-001 - 07222026
B3: Englewood, CO 80111
B4: Phone: 720-457-5500
B5: Fax: 720-242-8085
B6: Support@SummitSensory.com
B8: CUSTOMER INFO | F8: PROPOSAL | H8: DATE
B9: =Discovery!B2 -> Tyler Galiotto | F9: ="ADV-" & UPPER(LEFT(B10,1) & RIGHT(B10,1)) & "-" & TEXT(H9,"yymmdd") & "-" & TEXT( IF(AND(ISNUMBER(K11),K11>0), K11, COUNTIFS($B$10:B10,B10,$H$9:H9,H9) ), "000") -> ADV-SS-260722-001 | H9: =TODAY() -> 46225
B10: =Discovery!B3 -> Soar Autism Center - South Fort Collins | F10: PROJECT ID # | H10: VALID UNTIL
B11: =Discovery!B4 -> 3801 Automation Way | F11: ="SSG-"&Discovery!B13 -> SSG-12552093278 | H11: =H9+6 -> 46231 | J11: Proposal # Override | K11: 0
B12: =Discovery!B5&" "&Discovery!B6 -> Fort Collins, CO 80525 | F12: FREIGHT WEIGHT (lbs) | H12: =Calcs!I176+100 -> 1376.862
B13: =Discovery!B10 -> United States | J13: Freight Weight Conversion
J14: lbs | K14: =H12 -> 1376.862
B15: PROPOSAL DETAILS | J15: kgs | K15: =K14/2.205 -> 624.42721
B16: ="Summit Adventure Series "&VLOOKUP!D1&" - "&Discovery!B28&"Design & Fabrication of "&(VLOOKUP!F9)&"' X "&(VLOOKUP!F10)&"' Sensory Gym Structure"&IF(Calcs!F22>0," w Monkey Bars","")&IF(Calcs!F47>0," & Trolley System","") -> Summit Adventure Series SQ-2MBL2T - Design & Fabrication of 10' X 10' Sensory Gym Structure w Monkey Bars & Trolley System
B19: DESCRIPTION | D19: SKU | F19: QTY | G19: UNIT PRICE (USD) | H19: AMOUNT
B20: =VLOOKUP!F1&" - ITEMIZED" -> SQ-2MBL2T-10x10 - ITEMIZED | F20: TITL
B21: =IFERROR(VLOOKUP(D21,Calcs!B:G,3,FALSE),"") -> Vertical Tall <80 w/Gusset | D21: A-2245 | F21: =IFERROR(VLOOKUP(D21,Calcs!B:F,5,FALSE),"") -> 2 | G21: =IFERROR(VLOOKUP(D21,Calcs!B:M,11,FALSE),"") -> 557.75 | H21: =IFERROR(VLOOKUP(D21,Calcs!B:M,12,FALSE),"") -> 1115.5
B22: =IFERROR(VLOOKUP(D22,Calcs!B:G,3,FALSE),"") -> Vertical Tall <80 w/Gussets, Rungs & Handles | D22: A-2246 | F22: =IFERROR(VLOOKUP(D22,Calcs!B:F,5,FALSE),"") -> 2 | G22: =IFERROR(VLOOKUP(D22,Calcs!B:M,11,FALSE),"") -> 557.75 | H22: =IFERROR(VLOOKUP(D22,Calcs!B:M,12,FALSE),"") -> 1115.5
B23: =IFERROR(VLOOKUP(D23,Calcs!B:G,3,FALSE),"") | D23: A-2241 | F23: =IFERROR(VLOOKUP(D23,Calcs!B:F,5,FALSE),"") | G23: =IFERROR(VLOOKUP(D23,Calcs!B:M,11,FALSE),"") | H23: =IFERROR(VLOOKUP(D23,Calcs!B:M,12,FALSE),"")
B24: =IFERROR(VLOOKUP(D24,Calcs!B:G,3,FALSE),"") -> Corner Post <80 2-Way Weld Assembly | D24: A-2242 | F24: =IFERROR(VLOOKUP(D24,Calcs!B:F,5,FALSE),"") -> 4 | G24: =IFERROR(VLOOKUP(D24,Calcs!B:M,11,FALSE),"") -> 175.95 | H24: =IFERROR(VLOOKUP(D24,Calcs!B:M,12,FALSE),"") -> 703.8
B25: =IFERROR(VLOOKUP(D25,Calcs!B:G,3,FALSE),"") | D25: A-2243 | F25: =IFERROR(VLOOKUP(D25,Calcs!B:F,5,FALSE),"") | G25: =IFERROR(VLOOKUP(D25,Calcs!B:M,11,FALSE),"") | H25: =IFERROR(VLOOKUP(D25,Calcs!B:M,12,FALSE),"")
B26: =IFERROR(VLOOKUP(D26,Calcs!B:G,3,FALSE),"") | D26: A-2244 | F26: =IFERROR(VLOOKUP(D26,Calcs!B:F,5,FALSE),"") | G26: =IFERROR(VLOOKUP(D26,Calcs!B:M,11,FALSE),"") | H26: =IFERROR(VLOOKUP(D26,Calcs!B:M,12,FALSE),"")
B27: =IFERROR(VLOOKUP(D27,Calcs!B:G,3,FALSE),"") | D27: A-2022 | F27: =IFERROR(VLOOKUP(D27,Calcs!B:F,5,FALSE),"") | G27: =IFERROR(VLOOKUP(D27,Calcs!B:M,11,FALSE),"") | H27: =IFERROR(VLOOKUP(D27,Calcs!B:M,12,FALSE),"")
B28: =IFERROR(VLOOKUP(D28,Calcs!B:G,3,FALSE),"") -> Mid Span 1-Way Saddle Alt Weld Assembly | D28: A-2225 | F28: =IFERROR(VLOOKUP(D28,Calcs!B:F,5,FALSE),"") -> 4 | G28: =IFERROR(VLOOKUP(D28,Calcs!B:M,11,FALSE),"") -> 105.8 | H28: =IFERROR(VLOOKUP(D28,Calcs!B:M,12,FALSE),"") -> 423.2
B29: =IFERROR(VLOOKUP(D29,Calcs!B:G,3,FALSE),"") -> Ladder Leg Footless | D29: P-2531 | F29: =IFERROR(VLOOKUP(D29,Calcs!B:F,5,FALSE),"") -> 2 | G29: =IFERROR(VLOOKUP(D29,Calcs!B:M,11,FALSE),"") -> 224.25 | H29: =IFERROR(VLOOKUP(D29,Calcs!B:M,12,FALSE),"") -> 448.5
B30: =IFERROR(VLOOKUP(D30,Calcs!B:G,3,FALSE),"") -> Single Leg Inner Ladder Sleeve Footless Weld Assembly | D30: A-2253 | F30: =IFERROR(VLOOKUP(D30,Calcs!B:F,5,FALSE),"") -> 2 | G30: =IFERROR(VLOOKUP(D30,Calcs!B:M,11,FALSE),"") -> 150.65 | H30: =IFERROR(VLOOKUP(D30,Calcs!B:M,12,FALSE),"") -> 301.3
B31: =IFERROR(VLOOKUP(D31,Calcs!B:G,3,FALSE),"") | D31: A-2248 | F31: =IFERROR(VLOOKUP(D31,Calcs!B:F,5,FALSE),"") | G31: =IFERROR(VLOOKUP(D31,Calcs!B:M,11,FALSE),"") | H31: =IFERROR(VLOOKUP(D31,Calcs!B:M,12,FALSE),"")
B32: =IFERROR(VLOOKUP(D32,Calcs!B:G,3,FALSE),"") | D32: P-2545 | F32: =IFERROR(VLOOKUP(D32,Calcs!B:F,5,FALSE),"") | G32: =IFERROR(VLOOKUP(D32,Calcs!B:M,11,FALSE),"") | H32: =IFERROR(VLOOKUP(D32,Calcs!B:M,12,FALSE),"")
... B50: =IFERROR(VLOOKUP(D50,Calcs!B:G,3,FALSE),"") | D50: P-1032 | F50: =IFERROR(VLOOKUP(D50,Calcs!B:F,5,FALSE),"") | G50: =IFERROR(VLOOKUP(D50,Calcs!B:M,11,FALSE),"") | H50: =IFERROR(VLOOKUP(D50,Calcs!B:M,12,FALSE),"")
B51: =IF(VLOOKUP!E14="yES","Professional Design & Rendering Consulting","") | D51: DESIGN | F51: =IFERROR(VLOOKUP(D51,Calcs!B:F,5,FALSE),"") | G51: =IFERROR(VLOOKUP(D51,Calcs!B:M,11,FALSE),"") | H51: =IFERROR(VLOOKUP(D51,Calcs!B:M,12,FALSE),"")
B52: SUBTOTAL | F52: SUB | H52: =SUM(H21:H51) -> 8223.65
F53: HOLD
B54: DUAL TROLLEY SYSTEM (Optional) | F54: TITL
B55: Unquoted | F55: UQ-TR
B56: =IFERROR(VLOOKUP(D56,Calcs!B:G,3,FALSE),"") -> Trolley Bar | D56: P-2018 | F56: =IFERROR(VLOOKUP(D56,Calcs!B:F,5,FALSE),"") -> 1 | G56: =IFERROR(VLOOKUP(D56,Calcs!B:M,11,FALSE),"") -> 32.2 | H56: =IFERROR(VLOOKUP(D56,Calcs!B:Z,12,FALSE),"") -> 32.2
B57: =IFERROR(VLOOKUP(D57,Calcs!B:G,3,FALSE),"") -> Trolley Bar Plate | D57: P-2025 | F57: =IFERROR(VLOOKUP(D57,Calcs!B:F,5,FALSE),"") -> 2 | G57: =IFERROR(VLOOKUP(D57,Calcs!B:M,11,FALSE),"") -> 27.6 | H57: =IFERROR(VLOOKUP(D57,Calcs!B:Z,12,FALSE),"") -> 55.2
B58: =IFERROR(VLOOKUP(D58,Calcs!B:G,3,FALSE),"") | D58: SSG-TR-A10 | F58: =IFERROR(VLOOKUP(D58,Calcs!B:F,5,FALSE),"") | G58: =IFERROR(VLOOKUP(D58,Calcs!B:M,11,FALSE),"") | H58: =IFERROR(VLOOKUP(D58,Calcs!B:Z,12,FALSE),"")
B59: =IFERROR(VLOOKUP(D59,Calcs!B:G,3,FALSE),"") -> 9' Aluminum Enclosed Rail 550lbs. Max Weight | D59: SSG-TR-A09 | F59: =IFERROR(VLOOKUP(D59,Calcs!B:F,5,FALSE),"") -> 2 | G59: =IFERROR(VLOOKUP(D59,Calcs!B:M,11,FALSE),"") -> 445.05 | H59: =IFERROR(VLOOKUP(D59,Calcs!B:Z,12,FALSE),"") -> 890.1
B60: =IFERROR(VLOOKUP(D60,Calcs!B:G,3,FALSE),"") | D60: SSG-TR-A08 | F60: =IFERROR(VLOOKUP(D60,Calcs!B:F,5,FALSE),"") | G60: =IFERROR(VLOOKUP(D60,Calcs!B:M,11,FALSE),"") | H60: =IFERROR(VLOOKUP(D60,Calcs!B:Z,12,FALSE),"")
...

Sheet LOAN CALC - INCLUDE
L1: PREFERRED LEASE RATES | U1: File Name: | V1: =A9&" - Financing Options - Amount $"&TRUNC(A17)&" - "&TEXT(E7,"MMDDYYYY") -> Soar Autism Center - South Fort Collins - Financing Options - Amount $18229 - 07222026
L2: EQUIPMENT | N2: MONTHLY TERM
N3: 12 | O3: 24 | P3: 36 | Q3: 48 | R3: 60
L4: 3000 | M4: 4999 | N4: 0 | O4: 0.05622 | P4: 0.04088 | Q4: 0.03334 | R4: 0
L5: 5000 | M5: 9999 | N5: 0.0959 | O5: 0.05016 | P5: 0.03514 | Q5: 0.02769 | R5: 0.02324
L6: 10000 | M6: 14999 | N6: 0.09156 | O6: 0.04753 | P6: 0.03301 | Q6: 0.02577 | R6: 0.02144
A7: Customer Information | D7: Date Presented | E7: =TODAY() -> 46225 | L7: 15000 | M7: 24999 | N7: 0.0907 | O7: 0.04708 | P7: 0.0327 | Q7: 0.02553 | R7: 0.02124
A8: =ZAPIER!C5 -> Tyler Galiotto | L8: 25000 | M8: 34999 | N8: 0.08984 | O8: 0.04663 | P8: 0.03239 | Q8: 0.02528 | R8: 0.02104
A9: =ZAPIER!D5 -> Soar Autism Center - South Fort Collins | D9: Questions? Contact | L9: 35000 | M9: 49999 | N9: 0.08932 | O9: 0.04641 | P9: 0.03223 | Q9: 0.02516 | R9: 0.02094
A10: =ZAPIER!E5 -> 3801 Automation Way | D10: Chandler Kinsey | L10: 50000 | M10: 74999 | N10: 0.08889 | O10: 0.04608 | P10: 0.03197 | Q10: 0.02494 | R10: 0.02073
A11: =ZAPIER!G5&", "&ZAPIER!H5&" "&ZAPIER!I5 -> CO, 80525 United States | D11: 800-541-6370 | L11: 75000 | M11: 99999 | N11: 0.08846 | O11: 0.04586 | P11: 0.03182 | Q11: 0.02482 | R11: 0.02063
A12: =ZAPIER!K5 | D12: ckinsey@ryancapital.com | L12: 100000 | M12: 199999 | N12: 0.08802 | O12: 0.04563 | P12: 0.03166 | Q12: 0.02469 | R12: 0.02053
A13: =ZAPIER!#REF! -> #REF!
A16: Estimated Loan Amount | C16: Term (Months) | D16: 12 | E16: 24 | F16: 36 | G16: 48 | H16: 60
A17: ='Adventure Series Proposal (USA)'!H238 -> 18229.05 | C17: Monthly Payment | D17: {=_xlfn.IFS($A$17<$L$4,"",$A$17<$L$5,$A$17*N4,$A$17<$L$6,$A$17*N5,$A$17<$L$7,$A$17*N6,$A$17<$L$8,$A$17*N7,$A$17<$L$9,$A$17*N8,$A$17<$L$10,$A$17*N9,$A$17>$M$9,"OVER",TRUE,"")} -> 1653.3748 | E17: {=_xlfn.IFS($A$17<$L$4,"",$A$17<$L$5,$A$17*O4,$A$17<$L$6,$A$17*O5,$A$17<$L$7,$A$17*O6,$A$17<$L$8,$A$17*O7,$A$17<$L$9,$A$17*O8,$A$17<$L$10,$A$17*O9,$A$17>$M$9,"OVER",TRUE,"")} -> 858.22367 | F17: {=_xlfn.IFS($A$17<$L$4,"",$A$17<$L$5,$A$17*P4,$A$17<$L$6,$A$17*P5,$A$17<$L$7,$A$17*P6,$A$17<$L$8,$A$17*P7,$A$17<$L$9,$A$17*P8,$A$17<$L$10,$A$17*P9,$A$17>$M$9,"OVER",TRUE,"")} -> 596.08993 | G17: {=_xlfn.IFS($A$17<$L$4,"",$A$17<$L$5,$A$17*Q4,$A$17<$L$6,$A$17*Q5,$A$17<$L$7,$A$17*Q6,$A$17<$L$8,$A$17*Q7,$A$17<$L$9,$A$17*Q8,$A$17<$L$10,$A$17*Q9,$A$17>$M$9,"OVER",TRUE,"")} -> 465.38765 | H17: {=_xlfn.IFS($A$17<$L$4,"",$A$17<$L$5,$A$17*R4,$A$17<$L$6,$A$17*R5,$A$17<$L$7,$A$17*R6,$A$17<$L$8,$A$17*R7,$A$17<$L$9,$A$17*R8,$A$17<$L$10,$A$17*R9,$A$17>$M$9,"OVER",TRUE,"")} -> 387.18502
C19: First & Last Payment in Advance
C20: (Payments are Subject to Credit Approval)
A22: Tax Benefits
A25: Section 179 Business Deduction:
A26: Businesses may immediately expense the cost of any Section 179 property and deduct the expense in the year the property is placed into service. The new maximum deduction is 1 million.
A28: Tax Benefit for this Investment:
A29: Cost of Equipment | D29: =A17 -> 18229.05
A30: Section 179 Deduction | D30: =D29 -> 18229.05
A31: 50% Bonus Depreciation | D31: 0
A32: Regular First Year Depreciation Deduction | D32: 0
A33: Total First Year Deduction | D33: =D30 -> 18229.05
A35: Cash Savings on Your Equipment Purchase | D35: =D33*0.21 -> 3828.1005
A36: % Savings on Your Equipment Purchase | D36: =D35/D33 -> 0.21
A38: Net Cost of Equipment After Tax Deductions | D38: =D33-D35 -> 14400.949
A40: What Does Net Cost of Equipment After Tax Deductions Mean?
A41: This represents the actual cost of the equipment once the value of tax deductions/credits is applied. In other words, it’s the net cost to your organization after factoring in tax savings—making it a more accurate reflection of the investment.

Sheet Adventure Series Proposal (CAN)
B1: Summit Sensory Gym | J1: PSF File Name | K1: =B10&" - "&VLOOKUP!F1&" - PSFv73 - "&TEXT(H9,"MMDDYYYY") -> Soar Autism Center - South Fort Collins - SQ-2MBL2T-10x10 - PSFv73 - 07222026
B2: 6150 S Geneva Court | J2: Proposal File Name | K2: =B10&" - "&VLOOKUP!F1&" - Proposal "&F9&" - "&TEXT(H9,"MMDDYYYY") -> Soar Autism Center - South Fort Collins - SQ-2MBL2T-10x10 - Proposal ADV-SS-260722-001 - 07222026
B3: Englewood, CO 80111
B4: Phone: 720-457-5500
B5: Fax: 720-242-8085
B6: Support@SummitSensory.com
B8: CUSTOMER INFO | F8: PROPOSAL | H8: DATE
B9: =Discovery!B2 -> Tyler Galiotto | F9: ="ADV-" & UPPER(LEFT(B10,1) & RIGHT(B10,1)) & "-" & TEXT(H9,"yymmdd") & "-" & TEXT( IF(AND(ISNUMBER(K11),K11>0), K11, COUNTIFS($B$10:B10,B10,$H$9:H9,H9) ), "000") -> ADV-SS-260722-001 | H9: =TODAY() -> 46225
B10: =Discovery!B3 -> Soar Autism Center - South Fort Collins | F10: PROJECT ID # | H10: VALID UNTIL
B11: =Discovery!B4 -> 3801 Automation Way | F11: ="SSG-"&Discovery!B13 -> SSG-12552093278 | H11: =H9+6 -> 46231 | J11: Proposal # Override | K11: 0
B12: =Discovery!B5&" "&Discovery!B6 -> Fort Collins, CO 80525 | F12: FREIGHT WEIGHT (lbs) | H12: =Calcs!I176+100 -> 1376.862
B13: =Discovery!B10 -> United States | J13: Freight Weight Conversion
J14: lbs | K14: =H12 -> 1376.862
B15: PROPOSAL DETAILS | J15: kgs | K15: =K14/2.205 -> 624.42721
B16: ="Summit Adventure Series "&VLOOKUP!D1&" - "&Discovery!B28&"Design & Fabrication of "&(VLOOKUP!F9)&"' X "&(VLOOKUP!F10)&"' Sensory Gym Structure"&IF(Calcs!F22>0," w Monkey Bars","")&IF(Calcs!F47>0," & Trolley System","") -> Summit Adventure Series SQ-2MBL2T - Design & Fabrication of 10' X 10' Sensory Gym Structure w Monkey Bars & Trolley System
B19: DESCRIPTION | D19: SKU | F19: QTY | G19: UNIT PRICE (USD) | H19: AMOUNT
B20: =VLOOKUP!F1&" - ITEMIZED" -> SQ-2MBL2T-10x10 - ITEMIZED | F20: TITL
B21: =IFERROR(VLOOKUP(D21,Calcs!B:G,3,FALSE),"") -> Vertical Tall <80 w/Gusset | D21: A-2245 | F21: =IFERROR(VLOOKUP(D21,Calcs!B:F,5,FALSE),"") -> 2 | G21: =IFERROR(VLOOKUP(D21,Calcs!B:M,11,FALSE),"") -> 557.75 | H21: =IFERROR(VLOOKUP(D21,Calcs!B:M,12,FALSE),"") -> 1115.5
B22: =IFERROR(VLOOKUP(D22,Calcs!B:G,3,FALSE),"") -> Vertical Tall <80 w/Gussets, Rungs & Handles | D22: A-2246 | F22: =IFERROR(VLOOKUP(D22,Calcs!B:F,5,FALSE),"") -> 2 | G22: =IFERROR(VLOOKUP(D22,Calcs!B:M,11,FALSE),"") -> 557.75 | H22: =IFERROR(VLOOKUP(D22,Calcs!B:M,12,FALSE),"") -> 1115.5
B23: =IFERROR(VLOOKUP(D23,Calcs!B:G,3,FALSE),"") | D23: A-2241 | F23: =IFERROR(VLOOKUP(D23,Calcs!B:F,5,FALSE),"") | G23: =IFERROR(VLOOKUP(D23,Calcs!B:M,11,FALSE),"") | H23: =IFERROR(VLOOKUP(D23,Calcs!B:M,12,FALSE),"")
B24: =IFERROR(VLOOKUP(D24,Calcs!B:G,3,FALSE),"") -> Corner Post <80 2-Way Weld Assembly | D24: A-2242 | F24: =IFERROR(VLOOKUP(D24,Calcs!B:F,5,FALSE),"") -> 4 | G24: =IFERROR(VLOOKUP(D24,Calcs!B:M,11,FALSE),"") -> 175.95 | H24: =IFERROR(VLOOKUP(D24,Calcs!B:M,12,FALSE),"") -> 703.8
B25: =IFERROR(VLOOKUP(D25,Calcs!B:G,3,FALSE),"") | D25: A-2243 | F25: =IFERROR(VLOOKUP(D25,Calcs!B:F,5,FALSE),"") | G25: =IFERROR(VLOOKUP(D25,Calcs!B:M,11,FALSE),"") | H25: =IFERROR(VLOOKUP(D25,Calcs!B:M,12,FALSE),"")
B26: =IFERROR(VLOOKUP(D26,Calcs!B:G,3,FALSE),"") | D26: A-2244 | F26: =IFERROR(VLOOKUP(D26,Calcs!B:F,5,FALSE),"") | G26: =IFERROR(VLOOKUP(D26,Calcs!B:M,11,FALSE),"") | H26: =IFERROR(VLOOKUP(D26,Calcs!B:M,12,FALSE),"")
B27: =IFERROR(VLOOKUP(D27,Calcs!B:G,3,FALSE),"") | D27: A-2022 | F27: =IFERROR(VLOOKUP(D27,Calcs!B:F,5,FALSE),"") | G27: =IFERROR(VLOOKUP(D27,Calcs!B:M,11,FALSE),"") | H27: =IFERROR(VLOOKUP(D27,Calcs!B:M,12,FALSE),"")
B28: =IFERROR(VLOOKUP(D28,Calcs!B:G,3,FALSE),"") -> Mid Span 1-Way Saddle Alt Weld Assembly | D28: A-2225 | F28: =IFERROR(VLOOKUP(D28,Calcs!B:F,5,FALSE),"") -> 4 | G28: =IFERROR(VLOOKUP(D28,Calcs!B:M,11,FALSE),"") -> 105.8 | H28: =IFERROR(VLOOKUP(D28,Calcs!B:M,12,FALSE),"") -> 423.2
B29: =IFERROR(VLOOKUP(D29,Calcs!B:G,3,FALSE),"") -> Ladder Leg Footless | D29: P-2531 | F29: =IFERROR(VLOOKUP(D29,Calcs!B:F,5,FALSE),"") -> 2 | G29: =IFERROR(VLOOKUP(D29,Calcs!B:M,11,FALSE),"") -> 224.25 | H29: =IFERROR(VLOOKUP(D29,Calcs!B:M,12,FALSE),"") -> 448.5
